Workbook

Sheet Diretriz
A1: Número da Diretriz | B1: Diretriz
A2: 1 | B2: Garantir o acesso da população às ações e serviços da saúde como direito fundamental ao atendimento das necessidades de saúde, mediante o aprimoramento da política de atenção primária, vigilância em saúde e garantindo o acesso a medicamentos e insumos estratégicos no âmbito do SUS.
A3: 2 | B3: Fortalecimento da Assistência Especializada em Saúde, de Média e Alta Complexidade, de forma ascendente e regionalizada, contemplando as demandas específicas das regiões de saúde, aperfeiçoando o sistema de regulação, garantindo a oferta de serviços de saúde.
A4: 3 | B4: Fortalecer a Gestão Pública, por meio da gestão compartilhada nas regiões de saúde, com aprimoramento do planejamento estratégico e dos instrumentos de gestão, garantindo e fortalecendo as instâncias de controle social.
A5: 4 | B5: Garantir o financiamento público e sustentável ao Sistema Único de Saúde, melhorando o padrão de gastos e qualificando o financiamento tripartite em saúde.

Sheet Objetivo
A1: Número da Diretriz | B1: Diretriz | C1: Número do Objeto | D1: Objetivo
A2: 1 | B2: =_xlfn.XLOOKUP(A2,Diretriz!A:A,Diretriz!B:B) -> Garantir o acesso da população às ações e serviços da saúde como direito fundamental ao atendimento das necessidades de saúde, mediante o aprimoramento da política de atenção primária, vigilância em saúde e garantindo o acesso a medicamentos e insumos estratégicos no âmbito do SUS. | C2: 1.1 | D2: Fortalecer a Atenção Primária para apoiar o desenvolvimento de ações em saúde no estado.
A3: 1 | B3: =_xlfn.XLOOKUP(A3,Diretriz!A:A,Diretriz!B:B) -> Garantir o acesso da população às ações e serviços da saúde como direito fundamental ao atendimento das necessidades de saúde, mediante o aprimoramento da política de atenção primária, vigilância em saúde e garantindo o acesso a medicamentos e insumos estratégicos no âmbito do SUS. | C3: 1.2 | D3: Aprimorar as ações de Vigilância em Saúde para promoção, prevenção e controle de doenças e agravos.
A4: 1 | B4: =_xlfn.XLOOKUP(A4,Diretriz!A:A,Diretriz!B:B) -> Garantir o acesso da população às ações e serviços da saúde como direito fundamental ao atendimento das necessidades de saúde, mediante o aprimoramento da política de atenção primária, vigilância em saúde e garantindo o acesso a medicamentos e insumos estratégicos no âmbito do SUS. | C4: 1.3 | D4: Garantir aos usuários do SUS acesso aos medicamentos contemplados nos Componentes Básico, Especializado, Estratégico da Assistência Farmacêutica e dos programas da SES/MA.
A5: 2 | B5: =_xlfn.XLOOKUP(A5,Diretriz!A:A,Diretriz!B:B) -> Fortalecimento da Assistência Especializada em Saúde, de Média e Alta Complexidade, de forma ascendente e regionalizada, contemplando as demandas específicas das regiões de saúde, aperfeiçoando o sistema de regulação, garantindo a oferta de serviços de saúde. | C5: 2.1 | D5: Garantir a integralidade da assistência dos serviços de média e alta complexidade aos usuários do SUS, por meio do fortalecimento das redes de atenção à saúde.
A6: 2 | B6: =_xlfn.XLOOKUP(A6,Diretriz!A:A,Diretriz!B:B) -> Fortalecimento da Assistência Especializada em Saúde, de Média e Alta Complexidade, de forma ascendente e regionalizada, contemplando as demandas específicas das regiões de saúde, aperfeiçoando o sistema de regulação, garantindo a oferta de serviços de saúde. | C6: 2.2 | D6: Ampliar a doação e a captação de órgãos e tecidos, com a finalidade de ampliar a realização de transplantes no estado.
A7: 2 | B7: =_xlfn.XLOOKUP(A7,Diretriz!A:A,Diretriz!B:B) -> Fortalecimento da Assistência Especializada em Saúde, de Média e Alta Complexidade, de forma ascendente e regionalizada, contemplando as demandas específicas das regiões de saúde, aperfeiçoando o sistema de regulação, garantindo a oferta de serviços de saúde. | C7: 2.3 | D7: Programar, executar e coordenar a política de sangue, seus componentes e derivados no estado do Maranhão no âmbito da hemoterapia e de hematologia clínica, incluindo suporte diagnostico e atendimentos multidisciplinares.
A8: 2 | B8: =_xlfn.XLOOKUP(A8,Diretriz!A:A,Diretriz!B:B) -> Fortalecimento da Assistência Especializada em Saúde, de Média e Alta Complexidade, de forma ascendente e regionalizada, contemplando as demandas específicas das regiões de saúde, aperfeiçoando o sistema de regulação, garantindo a oferta de serviços de saúde. | C8: 2.4 | D8: Realizar assistência de combate ao cancer na média e alta complexidade.
A9: 2 | B9: =_xlfn.XLOOKUP(A9,Diretriz!A:A,Diretriz!B:B) -> Fortalecimento da Assistência Especializada em Saúde, de Média e Alta Complexidade, de forma ascendente e regionalizada, contemplando as demandas específicas das regiões de saúde, aperfeiçoando o sistema de regulação, garantindo a oferta de serviços de saúde. | C9: 2.5 | D9: Ampliar e modernizar a infraestrutura de unidades de saúde, de acordo com perfil assistencial definido.
A10: 3 | B10: =_xlfn.XLOOKUP(A10,Diretriz!A:A,Diretriz!B:B) -> Fortalecer a Gestão Pública, por meio da gestão compartilhada nas regiões de saúde, com aprimoramento do planejamento estratégico e dos instrumentos de gestão, garantindo e fortalecendo as instâncias de controle social. | C10: 3.1 | D10: Aprimorar o planejamento, o monitoramento e a avaliação da política de saúde, a nível estadual, e apoiar os municípios no âmbito da gestão do SUS.
A11: 3 | B11: =_xlfn.XLOOKUP(A11,Diretriz!A:A,Diretriz!B:B) -> Fortalecer a Gestão Pública, por meio da gestão compartilhada nas regiões de saúde, com aprimoramento do planejamento estratégico e dos instrumentos de gestão, garantindo e fortalecendo as instâncias de controle social. | C11: 3.2 | D11: Dimensionar, valorizar e qualificar os trabalhadores/as do SUS no Maranhão, a partir da estruturação de uma política da gestão de trabalho e educação na saúde.
A12: 3 | B12: =_xlfn.XLOOKUP(A12,Diretriz!A:A,Diretriz!B:B) -> Fortalecer a Gestão Pública, por meio da gestão compartilhada nas regiões de saúde, com aprimoramento do planejamento estratégico e dos instrumentos de gestão, garantindo e fortalecendo as instâncias de controle social. | C12: 3.3 | D12: Fortalecer os espaços de gestão compartilhada e descentralizada das ações da Secretaria Estadual de Saúde, visando à transparência e aprimorando o controle social.
A13: 4 | B13: =_xlfn.XLOOKUP(A13,Diretriz!A:A,Diretriz!B:B) -> Garantir o financiamento público e sustentável ao Sistema Único de Saúde, melhorando o padrão de gastos e qualificando o financiamento tripartite em saúde. | C13: 4.1 | D13: Garantir os investimentos em ações e serviços de saúde no Estado do Maranhão, ampliando o cofinanciamento, a captação de recursos e aumentando a eficiência, eficácia e efetividade da execução orçamentária e financeira

Sheet Meta
A1: Número da Diretriz | B1: Número do Objetivo | C1: Numero da meta | D1: Descrição da Meta | E1: Indicador da Meta | F1: Unidade de Medida | G1: Valor da Meta Planejada da PES | H1: Valor da Meta Planejada do Ano
A2: 1 | B2: 1.1 | C2: 1.1.1 | D2: Apoiar os municípios no desenvolvimento de ações de fortalecimento para Estratégia Saúde da Família | E2: Nº de municípios beneficiados | F2: Número | G2: 217 | H2: 49
A3: 1 | B3: 1.1 | C3: 1.1.2 | D3: Apoiar os municípios no desenvolvimento de ações voltadas para o fortalecimento da Política de Saúde Bucal. | E3: Nº de municípios beneficiados | F3: Número | G3: 217 | H3: 54
A4: 1 | B4: 1.1 | C4: 1.1.3 | D4: Apoiar os municípios a desenvolverem ações de fortalecimento da Política de Saúde do Adulto e Idoso. | E4: Nº de municípios beneficiados | F4: Número | G4: 217 | H4: 52
A5: 1 | B5: 1.1 | C5: 1.1.4 | D5: Apoiar Unidades Prisionais de Ressocialização a desenvolverem ações voltadas para a Política Nacional de Atenção Integral à Saúde de Pessoas Privadas de Liberdade (PNAISP). | E5: Nº de Unidades Prisionais apoiadas | F5: Número | G5: 47 | H5: 47
A6: 1 | B6: 1.1 | C6: 1.1.5 | D6: Apoiar os municípios no desenvolvimento de ações de fortalecimento da Política de Saúde Integral da Mulher. | E6: Nº de municípios beneficiados | F6: Número | G6: 217 | H6: 56
A7: 1 | B7: 1.1 | C7: 1.1.6 | D7: Apoiar os municípios no desenvolvimento de ações voltadas para o fortalecimento da Política de Saúde da Criança e do Adolescente. | E7: Nº de municípios beneficiados | F7: Número | G7: 217 | H7: 43
A8: 1 | B8: 1.1 | C8: 1.1.7 | D8: Apoiar os municípios para implantação e implementação das ações e estratégias da Política Nacional de Alimentação e Nutrição (PNAN). | E8: Nº de municípios beneficiados | F8: Número | G8: 217 | H8: 45
A9: 1 | B9: 1.1 | C9: 1.1.8 | D9: Fortalecer os municípios na integração das ações da Atenção Primária com as populações vulneráveis seguindo o princípio da Equidade em Saúde. | E9: Nº de municípios beneficiados | F9: Número | G9: 217 | H9: 58
A10: 1 | B10: 1.1 | C10: 1.1.9 | D10: Apoiar institucionalmente as gestões municipais no SUS, por meio da planificação da atenção à saúde e da oferta de assistência em situação de emergência de saúde pública. | E10: Nº de municípios beneficiados | F10: Número | G10: 217 | H10: 60
A11: 1 | B11: 1.1 | C11: 1.1.10 | D11: Garantir apoio institucional aos municípios nas ações da Política de Saúde Mental, Álcool e outras drogas. | E11: Nº de municípios beneficiados | F11: Número | G11: 217 | H11: 46
A12: 1 | B12: 1.1 | C12: 1.1.11 | D12: Reduzir em 60% a internação de longa permanência de pessoas com transtornos mentais em conflito com a lei. | E12: Nº de internações | F12: Número | G12: 402 | H12: 447
A13: 1 | B13: 1.1 | C13: 1.1.12 | D13: Apoiar os municípios na implantação do Programa Farmácia Viva. | E13: Nº de municípios beneficiados | F13: Número | G13: 217 | H13: 55
... A28: 2 | B28: 2.1 | C28: 2.1.3 | D28: Garantir o atendimento Odontológico Ambulatorial, Hospitalar e de Urgência e Emergência. | E28: Nº de procedimentos realizados | F28: Unidade | G28: 1437206 | H28: 361071
A29: 2 | B29: 2.1 | C29: 2.1.4 | D29: Otimizar o gerenciamento dos leitos hospitalares da rede própria. | E29: % de Leitos Monitorados | F29: Porcentagem | G29: 0.85 | H29: 0.75
A30: 2 | B30: 2.1 | C30: 2.1.5 | D30: Qualificar os processos de regulação de acesso ambulatorial. | E30: % de solicitações atendidas | F30: Porcentagem | G30: 1 | H30: 0.9
A31: 2 | B31: 2.1 | C31: 2.1.6 | D31: Qualificar os processos de regulação de acesso à internação hospitalar. | E31: % solicitações atendidas | F31: Porcentagem | G31: 1 | H31: 0.99
A32: 2 | B32: 2.1 | C32: 2.1.7 | D32: Qualificar os processos de regulação de transporte interhospitalar. | E32: % de solicitações atendidas | F32: Porcentagem | G32: 1 | H32: 0.96
A33: 2 | B33: 2.1 | C33: 2.1.8 | D33: Garantir o deslocamento e ajuda de custo aos pacientes para Tratamentos Fora do Domicílio (TFD) em outra unidade da federação. | E33: Nº de procedimentos realizados | F33: Unidade | G33: 386800 | H33: 96700
A34: 2 | B34: 2.1 | C34: 2.1.9 | D34: Prestar o atendimento ambulatorial e hospitalar de média e alta complexidade aos usuários do SUS por intermédio dos estabelecimentos de saúde de natureza pública municipal e privadas contratualizadas. | E34: Nº de procedimentos realizados | F34: Unidade | G34: 5491073 | H34: 1404578
A35: 2 | B35: 2.1 | C35: 2.1.10 | D35: Garantir apoio técnico aos municípios com Serviço de Atendimento Móvel de Urgência (SAMU) habilitados. | E35: Nº de municípios beneficiados | F35: Unidade | G35: 64 | H35: 60
A36: 2 | B36: 2.2 | C36: 2.2.1 | D36: Aumentar o número de notificações de morte encefálica e tecidos no estado. | E36: Nº de notificações | F36: Unidade | G36: 858 | H36: 223
A37: 2 | B37: 2.2 | C37: 2.2.2 | D37: Aumentar o número de doadores efetivos para doação e captação de órgãos e tecidos | E37: Nº de doadores efetivos | F37: Unidade | G37: 60 | H37: 16
A38: 2 | B38: 2.2 | C38: 2.2.3 | D38: Aumentar o número de transplantes de órgãos e tecidos efetivos no estado. | E38: Nº de transplantes efetivos no Estado | F38: Unidade | G38: 133 | H38: 35
A39: 2 | B39: 2.3 | C39: 2.3.1 | D39: Ampliar os procedimentos destinados à obtenção do sangue, seus componentes e derivados. | E39: Nº de procedimentos hemoterápicos realizados | F39: Unidade | G39: 1905845 | H39: 492500
A40: 2 | B40: 2.3 | C40: 2.3.2 | D40: Ampliar o número de consultas médicas em atenção especializada. | E40: Nº de consultas médicas realizadas | F40: Unidade | G40: 117600 | H40: 29200
A41: 2 | B41: 2.3 | C41: 2.3.3 | D41: Ampliar o número de atendimentos multidisciplinares em atenção especializada. | E41: Nº de atendimentos multidisciplinares realizados | F41: Unidade | G41: 118104 | H41: 31200
... A62: 4 | B62: 4.1 | C62: 4.1.4 | D62: Garantir o repasse do Serviço Móvel de Urgência (SAMU) aos municípios. | E62: Nº de parcelas de repasse realizadas | F62: Unidade | G62: 2784 | H62: 720

Sheet Atividade
A1: Número da Diretriz | B1: Diretriz | C1: Número do Objeto | D1: Objetivo | E1: Numero da meta | F1: Descrição da Meta | G1: Número da Atividade | H1: Descrição da Atividade | I1: Indicador da Atividade | J1: Unidade de Medida | K1: Meta da Atividade
A2: 1 | B2: =IFERROR((_xlfn.XLOOKUP(A2,Diretriz!A:A,Diretriz!B:B)),"") -> Garantir o acesso da população às ações e serviços da saúde como direito fundamental ao atendimento das necessidades de saúde, mediante o aprimoramento da política de atenção primária, vigilância em saúde e garantindo o acesso a medicamentos e insumos estratégicos no âmbito do SUS. | C2: 1.1 | D2: =IFERROR((_xlfn.XLOOKUP(C2,Objetivo!C:C,Objetivo!D:D)), "") -> Fortalecer a Atenção Primária para apoiar o desenvolvimento de ações em saúde no estado. | E2: 1.1.1 | F2: =IFERROR(_xlfn.XLOOKUP(E2,#REF!,#REF!), "") | G2: 1.1.1.1 | H2: Realizar Apoio técnico por meio de monitoramento, visita técnica ou webconferência, objetivando incentivar os municípios a ampliarem a cobertura da Atenção Primária em Saúde (APS) no Estado, através da solicitação de novos credenciamentos de Programas, Projetos e Estratégias financiadas pelo Ministério da Saúde | I2: Ações Realizadas | J2: Unidade | K2: 49
A3: 1 | B3: =IFERROR((_xlfn.XLOOKUP(A3,Diretriz!A:A,Diretriz!B:B)),"") -> Garantir o acesso da população às ações e serviços da saúde como direito fundamental ao atendimento das necessidades de saúde, mediante o aprimoramento da política de atenção primária, vigilância em saúde e garantindo o acesso a medicamentos e insumos estratégicos no âmbito do SUS. | C3: 1.1 | D3: =IFERROR((_xlfn.XLOOKUP(C3,Objetivo!C:C,Objetivo!D:D)), "") -> Fortalecer a Atenção Primária para apoiar o desenvolvimento de ações em saúde no estado. | E3: 1.1.1 | F3: =IFERROR(_xlfn.XLOOKUP(E3,#REF!,#REF!), "") | G3: 1.1.1.2 | H3: Apoiar tecnicamente os municípios em relação aos Indicadores da APS, quanto ao registro das atividades realizadas ou subnotificadas no âmbito da Atenção Primária em Saúde, no Sistema E-SUS e Sistema de Informação da Atenção Primária em Saúde - SIAPS, através de web conferência e visita in loco | I3: Atividades Realizadas | J3: Unidade | K3: 6
A4: 1 | B4: =IFERROR((_xlfn.XLOOKUP(A4,Diretriz!A:A,Diretriz!B:B)),"") -> Garantir o acesso da população às ações e serviços da saúde como direito fundamental ao atendimento das necessidades de saúde, mediante o aprimoramento da política de atenção primária, vigilância em saúde e garantindo o acesso a medicamentos e insumos estratégicos no âmbito do SUS. | C4: 1.1 | D4: =IFERROR((_xlfn.XLOOKUP(C4,Objetivo!C:C,Objetivo!D:D)), "") -> Fortalecer a Atenção Primária para apoiar o desenvolvimento de ações em saúde no estado. | E4: 1.1.1 | F4: =IFERROR(_xlfn.XLOOKUP(E4,#REF!,#REF!), "") | G4: 1.1.1.3 | H4: Realizar monitoramento e avaliação através de oficinas presenciais e virtuais da Equipe Multiprofissional ¿ eMulti e Incentivo à Atividade Física ¿ IAF, credenciadas e homologadas, dos municípios. | I4: Atividades Realizadas | J4: Unidade | K4: 5
A5: 1 | B5: =IFERROR((_xlfn.XLOOKUP(A5,Diretriz!A:A,Diretriz!B:B)),"") -> Garantir o acesso da população às ações e serviços da saúde como direito fundamental ao atendimento das necessidades de saúde, mediante o aprimoramento da política de atenção primária, vigilância em saúde e garantindo o acesso a medicamentos e insumos estratégicos no âmbito do SUS. | C5: 1.1 | D5: =IFERROR((_xlfn.XLOOKUP(C5,Objetivo!C:C,Objetivo!D:D)), "") -> Fortalecer a Atenção Primária para apoiar o desenvolvimento de ações em saúde no estado. | E5: 1.1.1 | F5: =IFERROR(_xlfn.XLOOKUP(E5,#REF!,#REF!), "") | G5: 1.1.1.4 | H5: Realizar Oficinas de execução e monitoramento do Projeto: Linhas de Cuidados em Práticas Integrativas na Dor Crônica e Saúde Mental. | I5: Oficinas Realizadas | J5: Unidade | K5: 4
A6: 1 | B6: =IFERROR((_xlfn.XLOOKUP(A6,Diretriz!A:A,Diretriz!B:B)),"") -> Garantir o acesso da população às ações e serviços da saúde como direito fundamental ao atendimento das necessidades de saúde, mediante o aprimoramento da política de atenção primária, vigilância em saúde e garantindo o acesso a medicamentos e insumos estratégicos no âmbito do SUS. | C6: 1.1 | D6: =IFERROR((_xlfn.XLOOKUP(C6,Objetivo!C:C,Objetivo!D:D)), "") -> Fortalecer a Atenção Primária para apoiar o desenvolvimento de ações em saúde no estado. | E6: 1.1.1 | F6: =IFERROR(_xlfn.XLOOKUP(E6,#REF!,#REF!), "") | G6: 1.1.1.5 | H6: Realizar apoio técnico através de visita técnica ou web conferência, objetivando monitorar e qualificar as ações de segurança do paciente na APS | I6: Municípios Apoiados | J6: Unidade | K6: 4
A7: 1 | B7: =IFERROR((_xlfn.XLOOKUP(A7,Diretriz!A:A,Diretriz!B:B)),"") -> Garantir o acesso da população às ações e serviços da saúde como direito fundamental ao atendimento das necessidades de saúde, mediante o aprimoramento da política de atenção primária, vigilância em saúde e garantindo o acesso a medicamentos e insumos estratégicos no âmbito do SUS. | C7: 1.1 | D7: =IFERROR((_xlfn.XLOOKUP(C7,Objetivo!C:C,Objetivo!D:D)), "") -> Fortalecer a Atenção Primária para apoiar o desenvolvimento de ações em saúde no estado. | E7: 1.1.1 | F7: =IFERROR(_xlfn.XLOOKUP(E7,#REF!,#REF!), "") | G7: 1.1.1.6 | H7: Realizar Reunião da Câmara Técnica Estadual da APS. | I7: Reunião Realizada | J7: Unidade | K7: 1
A8: 1 | B8: =IFERROR((_xlfn.XLOOKUP(A8,Diretriz!A:A,Diretriz!B:B)),"") -> Garantir o acesso da população às ações e serviços da saúde como direito fundamental ao atendimento das necessidades de saúde, mediante o aprimoramento da política de atenção primária, vigilância em saúde e garantindo o acesso a medicamentos e insumos estratégicos no âmbito do SUS. | C8: 1.1 | D8: =IFERROR((_xlfn.XLOOKUP(C8,Objetivo!C:C,Objetivo!D:D)), "") -> Fortalecer a Atenção Primária para apoiar o desenvolvimento de ações em saúde no estado. | E8: 1.1.2 | F8: =IFERROR(_xlfn.XLOOKUP(E8,#REF!,#REF!), "") | G8: 1.1.2.1 | H8: Realizar Encontro Estadual de Atenção à Saúde Bucal com foco no apoio às gestões municipais para a melhoria da qualidade da oferta de serviços odontológicos. | I8: Encontro Realizado | J8: Unidade | K8: 1
A9: 1 | B9: =IFERROR((_xlfn.XLOOKUP(A9,Diretriz!A:A,Diretriz!B:B)),"") -> Garantir o acesso da população às ações e serviços da saúde como direito fundamental ao atendimento das necessidades de saúde, mediante o aprimoramento da política de atenção primária, vigilância em saúde e garantindo o acesso a medicamentos e insumos estratégicos no âmbito do SUS. | C9: 1.1 | D9: =IFERROR((_xlfn.XLOOKUP(C9,Objetivo!C:C,Objetivo!D:D)), "") -> Fortalecer a Atenção Primária para apoiar o desenvolvimento de ações em saúde no estado. | E9: 1.1.2 | F9: =IFERROR(_xlfn.XLOOKUP(E9,#REF!,#REF!), "") | G9: 1.1.2.2 | H9: Realizar Oficinas Macrorregionais, in loco ou via web, sobre a importância da Ampliação da Cobertura de Saúde Bucal na Atenção Primária em Saúde e melhora dos indicadores de desempenho | I9: Oficinas Realizadas | J9: Unidade | K9: 3
A10: 1 | B10: =IFERROR((_xlfn.XLOOKUP(A10,Diretriz!A:A,Diretriz!B:B)),"") -> Garantir o acesso da população às ações e serviços da saúde como direito fundamental ao atendimento das necessidades de saúde, mediante o aprimoramento da política de atenção primária, vigilância em saúde e garantindo o acesso a medicamentos e insumos estratégicos no âmbito do SUS. | C10: 1.1 | D10: =IFERROR((_xlfn.XLOOKUP(C10,Objetivo!C:C,Objetivo!D:D)), "") -> Fortalecer a Atenção Primária para apoiar o desenvolvimento de ações em saúde no estado. | E10: 1.1.2 | F10: =IFERROR(_xlfn.XLOOKUP(E10,#REF!,#REF!), "") | G10: 1.1.2.3 | H10: Apoiar tecnicamente os Municípios contemplados com Unidades Odontológicas Móveis (UOM) doadas pelo Ministério da Saúde (MS), em relação à situação de credenciamento/descredenciamento, cadastro, inconsistência, fluxos, Portarias, Notas Técnicas emitidas pelo Estado e MS. | I10: Municípios Apoiados | J10: Unidade | K10: 56
A11: 1 | B11: =IFERROR((_xlfn.XLOOKUP(A11,Diretriz!A:A,Diretriz!B:B)),"") -> Garantir o acesso da população às ações e serviços da saúde como direito fundamental ao atendimento das necessidades de saúde, mediante o aprimoramento da política de atenção primária, vigilância em saúde e garantindo o acesso a medicamentos e insumos estratégicos no âmbito do SUS. | C11: 1.1 | D11: =IFERROR((_xlfn.XLOOKUP(C11,Objetivo!C:C,Objetivo!D:D)), "") -> Fortalecer a Atenção Primária para apoiar o desenvolvimento de ações em saúde no estado. | E11: 1.1.3 | F11: =IFERROR(_xlfn.XLOOKUP(E11,#REF!,#REF!), "") | G11: 1.1.3.1 | H11: Realizar Seminários de qualificação para Profissionais de Saúde, Coordenadores da Saúde do Homem e Agentes Comunitários de Saúde - ACS sobre o fortalecimento da Política Nacional da Saúde Integral do Homem com foco no Acesso e Acolhimento, Pré-Natal do Parceiro e Prevenção, Diagnóstico e Tratamento do Câncer de Pênis baseado na Linha de Cuidado do Homem Maranhense. | I11: Seminários Realizados | J11: Unidade | K11: 2
A12: 1 | B12: =IFERROR((_xlfn.XLOOKUP(A12,Diretriz!A:A,Diretriz!B:B)),"") -> Garantir o acesso da população às ações e serviços da saúde como direito fundamental ao atendimento das necessidades de saúde, mediante o aprimoramento da política de atenção primária, vigilância em saúde e garantindo o acesso a medicamentos e insumos estratégicos no âmbito do SUS. | C12: 1.1 | D12: =IFERROR((_xlfn.XLOOKUP(C12,Objetivo!C:C,Objetivo!D:D)), "") -> Fortalecer a Atenção Primária para apoiar o desenvolvimento de ações em saúde no estado. | E12: 1.1.3 | F12: =IFERROR(_xlfn.XLOOKUP(E12,#REF!,#REF!), "") | G12: 1.1.3.2 | H12: Realizar Qualificação para Profissionais da Atenção Primária em Saúde, Coordenadores da Saúde da Pessoa Idosa e ACS em Avaliação Multidimensional, Violência, Promoção da Saúde e Prevenção de Quedas da Pessoa Idosa | I12: Seminários Realizados | J12: Unidade | K12: 2
A13: 1 | B13: =IFERROR((_xlfn.XLOOKUP(A13,Diretriz!A:A,Diretriz!B:B)),"") -> Garantir o acesso da população às ações e serviços da saúde como direito fundamental ao atendimento das necessidades de saúde, mediante o aprimoramento da política de atenção primária, vigilância em saúde e garantindo o acesso a medicamentos e insumos estratégicos no âmbito do SUS. | C13: 1.1 | D13: =IFERROR((_xlfn.XLOOKUP(C13,Objetivo!C:C,Objetivo!D:D)), "") -> Fortalecer a Atenção Primária para apoiar o desenvolvimento de ações em saúde no estado. | E13: 1.1.3 | F13: =IFERROR(_xlfn.XLOOKUP(E13,#REF!,#REF!), "") | G13: 1.1.3.3 | H13: Realizar Seminário de Qualificação para Profissionais da Atenção Primária em Saúde, para o Cuidado as Pessoas com Hipertensão Arterial Sistêmica e Diabetes Mellitus | I13: Seminários Realizados | J13: Unidade | K13: 2
... A172: 2 | B172: =IFERROR((_xlfn.XLOOKUP(A172,Diretriz!A:A,Diretriz!B:B)),"") -> Fortalecimento da Assistência Especializada em Saúde, de Média e Alta Complexidade, de forma ascendente e regionalizada, contemplando as demandas específicas das regiões de saúde, aperfeiçoando o sistema de regulação, garantindo a oferta de serviços de saúde. | C172: 2.1 | D172: =IFERROR((_xlfn.XLOOKUP(C172,Objetivo!C:C,Objetivo!D:D)), "") -> Garantir a integralidade da assistência dos serviços de média e alta complexidade aos usuários do SUS, por meio do fortalecimento das redes de atenção à saúde. | E172: 2.1.2 | F172: =IFERROR(_xlfn.XLOOKUP(E172,#REF!,#REF!), "") | G172: 2.1.2.9 | H172: Realizar 01 Simpósio Estadual em novembro sobre Qualidade nos Serviços de Saúde do Maranhão para discussões acerca de temáticas que perpassam o atendimento hospitalar. | I172: Simpósio Realizado | J172: Unidade | K172: 1
A173: 2 | B173: =IFERROR((_xlfn.XLOOKUP(A173,Diretriz!A:A,Diretriz!B:B)),"") -> Fortalecimento da Assistência Especializada em Saúde, de Média e Alta Complexidade, de forma ascendente e regionalizada, contemplando as demandas específicas das regiões de saúde, aperfeiçoando o sistema de regulação, garantindo a oferta de serviços de saúde. | C173: 2.1 | D173: =IFERROR((_xlfn.XLOOKUP(C173,Objetivo!C:C,Objetivo!D:D)), "") -> Garantir a integralidade da assistência dos serviços de média e alta complexidade aos usuários do SUS, por meio do fortalecimento das redes de atenção à saúde. | E173: 2.1.2 | F173: =IFERROR(_xlfn.XLOOKUP(E173,#REF!,#REF!), "") | G173: 2.1.2.10 | H173: Promover reconhecimento institucional de 100% das unidades estaduais que alcançarem alta conformidade na Avaliação Nacional das Práticas de Segurança do Paciente (Anvisa), incentivando a cultura de segurança | I173: Unidades em alta conformidade reconhecidas | J173: Porcentagem | K173: 100%
A174: 2 | B174: =IFERROR((_xlfn.XLOOKUP(A174,Diretriz!A:A,Diretriz!B:B)),"") -> Fortalecimento da Assistência Especializada em Saúde, de Média e Alta Complexidade, de forma ascendente e regionalizada, contemplando as demandas específicas das regiões de saúde, aperfeiçoando o sistema de regulação, garantindo a oferta de serviços de saúde. | C174: 2.1 | D174: =IFERROR((_xlfn.XLOOKUP(C174,Objetivo!C:C,Objetivo!D:D)), "") -> Garantir a integralidade da assistência dos serviços de média e alta complexidade aos usuários do SUS, por meio do fortalecimento das redes de atenção à saúde. | E174: 2.1.2 | F174: =IFERROR(_xlfn.XLOOKUP(E174,#REF!,#REF!), "") | G174: 2.1.2.11 | H174: Instituir a Comissão de Farmácia e Terapêutica da Secretaria de Estado da Saúde - CFT. | I174: Comissão Instituída | J174: Unidade | K174: 1
A175: 2 | B175: =IFERROR((_xlfn.XLOOKUP(A175,Diretriz!A:A,Diretriz!B:B)),"") -> Fortalecimento da Assistência Especializada em Saúde, de Média e Alta Complexidade, de forma ascendente e regionalizada, contemplando as demandas específicas das regiões de saúde, aperfeiçoando o sistema de regulação, garantindo a oferta de serviços de saúde. | C175: 2.1 | D175: =IFERROR((_xlfn.XLOOKUP(C175,Objetivo!C:C,Objetivo!D:D)), "") -> Garantir a integralidade da assistência dos serviços de média e alta complexidade aos usuários do SUS, por meio do fortalecimento das redes de atenção à saúde. | E175: 2.1.2 | F175: =IFERROR(_xlfn.XLOOKUP(E175,#REF!,#REF!), "") | G175: 2.1.2.12 | H175: Incentivar a participação das unidades de saúde por meio do acompanhamento e da aplicação dos resultados dos projetos do Programa de Apoio ao Desenvolvimento Institucional do Sistema Único de Saúde - PROADI-SUS. | I175: Unidades beneficiadas | J175: Porcentagem | K175: 100%
A176: 2 | B176: =IFERROR((_xlfn.XLOOKUP(A176,Diretriz!A:A,Diretriz!B:B)),"") -> Fortalecimento da Assistência Especializada em Saúde, de Média e Alta Complexidade, de forma ascendente e regionalizada, contemplando as demandas específicas das regiões de saúde, aperfeiçoando o sistema de regulação, garantindo a oferta de serviços de saúde. | C176: 2.1 | D176: =IFERROR((_xlfn.XLOOKUP(C176,Objetivo!C:C,Objetivo!D:D)), "") -> Garantir a integralidade da assistência dos serviços de média e alta complexidade aos usuários do SUS, por meio do fortalecimento das redes de atenção à saúde. | E176: 2.1.3 | F176: =IFERROR(_xlfn.XLOOKUP(E176,#REF!,#REF!), "") | G176: 2.1.3.1 | H176: Realizar a entrega de próteses dentárias nas Unidades de Especialidades Odontológicas - SORRIR | I176: Instalações Realizadas | J176: Unidade | K176: 5200
A177: 2 | B177: =IFERROR((_xlfn.XLOOKUP(A177,Diretriz!A:A,Diretriz!B:B)),"") -> Fortalecimento da Assistência Especializada em Saúde, de Média e Alta Complexidade, de forma ascendente e regionalizada, contemplando as demandas específicas das regiões de saúde, aperfeiçoando o sistema de regulação, garantindo a oferta de serviços de saúde. | C177: 2.1 | D177: =IFERROR((_xlfn.XLOOKUP(C177,Objetivo!C:C,Objetivo!D:D)), "") -> Garantir a integralidade da assistência dos serviços de média e alta complexidade aos usuários do SUS, por meio do fortalecimento das redes de atenção à saúde. | E177: 2.1.3 | F177: =IFERROR(_xlfn.XLOOKUP(E177,#REF!,#REF!), "") | G177: 2.1.3.2 | H177: Realizar procedimentos Odontológicos na Média e Alta complexidade. | I177: Procedimentos Realizados | J177: Unidade | K177: 750000
A178: 2 | B178: =IFERROR((_xlfn.XLOOKUP(A178,Diretriz!A:A,Diretriz!B:B)),"") -> Fortalecimento da Assistência Especializada em Saúde, de Média e Alta Complexidade, de forma ascendente e regionalizada, contemplando as demandas específicas das regiões de saúde, aperfeiçoando o sistema de regulação, garantindo a oferta de serviços de saúde. | C178: 2.1 | D178: =IFERROR((_xlfn.XLOOKUP(C178,Objetivo!C:C,Objetivo!D:D)), "") -> Garantir a integralidade da assistência dos serviços de média e alta complexidade aos usuários do SUS, por meio do fortalecimento das redes de atenção à saúde. | E178: 2.1.3 | F178: =IFERROR(_xlfn.XLOOKUP(E178,#REF!,#REF!), "") | G178: 2.1.3.3 | H178: Realizar encontros com a gestão das Unidades de Especialidades Odontológicas - SORRIR, para avaliação de indicadores e definição de ações estratégicas para melhoria em saúde bucal. | I178: Encontros Realizados | J178: Unidade | K178: 6
A179: 2 | B179: =IFERROR((_xlfn.XLOOKUP(A179,Diretriz!A:A,Diretriz!B:B)),"") -> Fortalecimento da Assistência Especializada em Saúde, de Média e Alta Complexidade, de forma ascendente e regionalizada, contemplando as demandas específicas das regiões de saúde, aperfeiçoando o sistema de regulação, garantindo a oferta de serviços de saúde. | C179: 2.1 | D179: =IFERROR((_xlfn.XLOOKUP(C179,Objetivo!C:C,Objetivo!D:D)), "") -> Garantir a integralidade da assistência dos serviços de média e alta complexidade aos usuários do SUS, por meio do fortalecimento das redes de atenção à saúde. | E179: 2.1.3 | F179: =IFERROR(_xlfn.XLOOKUP(E179,#REF!,#REF!), "") | G179: 2.1.3.4 | H179: Realizar Biopsias para diagnóstico precoce dos pacientes de Bucomaxilofacial do Hospital Dr. Tarquínio Lopes Filho. | I179: Biopsias Realizadas | J179: Unidade | K179: 50
A180: 2 | B180: =IFERROR((_xlfn.XLOOKUP(A180,Diretriz!A:A,Diretriz!B:B)),"") -> Fortalecimento da Assistência Especializada em Saúde, de Média e Alta Complexidade, de forma ascendente e regionalizada, contemplando as demandas específicas das regiões de saúde, aperfeiçoando o sistema de regulação, garantindo a oferta de serviços de saúde. | C180: 2.1 | D180: =IFERROR((_xlfn.XLOOKUP(C180,Objetivo!C:C,Objetivo!D:D)), "") -> Garantir a integralidade da assistência dos serviços de média e alta complexidade aos usuários do SUS, por meio do fortalecimento das redes de atenção à saúde. | E180: 2.1.3 | F180: =IFERROR(_xlfn.XLOOKUP(E180,#REF!,#REF!), "") | G180: 2.1.3.5 | H180: Implantar Núcleo de Segurança do Paciente (NSP) na Unidade de Especialidade Odontológicas - SORRIR do município de Caxias. | I180: Núcleo Implantado | J180: Unidade | K180: 1
A181: 2 | B181: =IFERROR((_xlfn.XLOOKUP(A181,Diretriz!A:A,Diretriz!B:B)),"") -> Fortalecimento da Assistência Especializada em Saúde, de Média e Alta Complexidade, de forma ascendente e regionalizada, contemplando as demandas específicas das regiões de saúde, aperfeiçoando o sistema de regulação, garantindo a oferta de serviços de saúde. | C181: 2.1 | D181: =IFERROR((_xlfn.XLOOKUP(C181,Objetivo!C:C,Objetivo!D:D)), "") -> Garantir a integralidade da assistência dos serviços de média e alta complexidade aos usuários do SUS, por meio do fortalecimento das redes de atenção à saúde. | E181: 2.1.3 | F181: =IFERROR(_xlfn.XLOOKUP(E181,#REF!,#REF!), "") | G181: 2.1.3.6 | H181: Implantar Serviço de Especialidades Odontológicas - SORRIR no município de Imperatriz. | I181: Serviço Implantado | J181: Unidade | K181: 1
A182: 2 | B182: =IFERROR((_xlfn.XLOOKUP(A182,Diretriz!A:A,Diretriz!B:B)),"") -> Fortalecimento da Assistência Especializada em Saúde, de Média e Alta Complexidade, de forma ascendente e regionalizada, contemplando as demandas específicas das regiões de saúde, aperfeiçoando o sistema de regulação, garantindo a oferta de serviços de saúde. | C182: 2.1 | D182: =IFERROR((_xlfn.XLOOKUP(C182,Objetivo!C:C,Objetivo!D:D)), "") -> Garantir a integralidade da assistência dos serviços de média e alta complexidade aos usuários do SUS, por meio do fortalecimento das redes de atenção à saúde. | E182: 2.1.3 | F182: =IFERROR(_xlfn.XLOOKUP(E182,#REF!,#REF!), "") | G182: 2.1.3.7 | H182: Implantar Serviço de Especialidades Odontológicas - SORRIR no município de Balsas | I182: Serviço Implantado | J182: Unidade | K182: 1
A183: 2 | B183: =IFERROR((_xlfn.XLOOKUP(A183,Diretriz!A:A,Diretriz!B:B)),"") -> Fortalecimento da Assistência Especializada em Saúde, de Média e Alta Complexidade, de forma ascendente e regionalizada, contemplando as demandas específicas das regiões de saúde, aperfeiçoando o sistema de regulação, garantindo a oferta de serviços de saúde. | C183: 2.1 | D183: =IFERROR((_xlfn.XLOOKUP(C183,Objetivo!C:C,Objetivo!D:D)), "") -> Garantir a integralidade da assistência dos serviços de média e alta complexidade aos usuários do SUS, por meio do fortalecimento das redes de atenção à saúde. | E183: 2.1.3 | F183: =IFERROR(_xlfn.XLOOKUP(E183,#REF!,#REF!), "") | G183: 2.1.3.8 | H183: Implantar Serviço de Especialidades Odontológicas - SORRIR no município de Barra do Corda. | I183: Serviço Implantado | J183: Unidade | K183: 1
A184: 2 | B184: =IFERROR((_xlfn.XLOOKUP(A184,Diretriz!A:A,Diretriz!B:B)),"") -> Fortalecimento da Assistência Especializada em Saúde, de Média e Alta Complexidade, de forma ascendente e regionalizada, contemplando as demandas específicas das regiões de saúde, aperfeiçoando o sistema de regulação, garantindo a oferta de serviços de saúde. | C184: 2.1 | D184: =IFERROR((_xlfn.XLOOKUP(C184,Objetivo!C:C,Objetivo!D:D)), "") -> Garantir a integralidade da assistência dos serviços de média e alta complexidade aos usuários do SUS, por meio do fortalecimento das redes de atenção à saúde. | E184: 2.1.4 | F184: =IFERROR(_xlfn.XLOOKUP(E184,#REF!,#REF!), "") | G184: 2.1.4.1 | H184: Apresentar relatório de monitoramento e análise dos indicadores gerenciais dos protocolos assistenciais estaduais (Sepse, Infarto Agudo do Miocárdio - IAM, Acidente Vascular Cerebral - AVC), com consolidação semestral dos resultados pelo setor de Qualidade e devolutiva às áreas técnicas responsáveis | I184: Relatórios Apresentados | J184: Unidade | K184: 2
A185: 2 | B185: =IFERROR((_xlfn.XLOOKUP(A185,Diretriz!A:A,Diretriz!B:B)),"") -> Fortalecimento da Assistência Especializada em Saúde, de Média e Alta Complexidade, de forma ascendente e regionalizada, contemplando as demandas específicas das regiões de saúde, aperfeiçoando o sistema de regulação, garantindo a oferta de serviços de saúde. | C185: 2.1 | D185: =IFERROR((_xlfn.XLOOKUP(C185,Objetivo!C:C,Objetivo!D:D)), "") -> Garantir a integralidade da assistência dos serviços de média e alta complexidade aos usuários do SUS, por meio do fortalecimento das redes de atenção à saúde. | E185: 2.1.4 | F185: =IFERROR(_xlfn.XLOOKUP(E185,#REF!,#REF!), "") | G185: 2.1.4.1 | H185: Realizar 02 (dois) fóruns anuais para análise consolidada dos indicadores dos leitos de Unidade de Terapia Intensiva - UTI e Unidade de Cuidados Intensivos - UCI (leitos complementares) abrangendo 100% das unidades hospitalares estaduais que dispõem de leitos complementares, assegurando que todas as unidades atinjam, no mínimo, 80% de preenchimento dos dados, de forma a garantir a confiabilidade das informações. | I185: Fóruns Realizados | J185: Unidade | K185: 2
A186: 2 | B186: =IFERROR((_xlfn.XLOOKUP(A186,Diretriz!A:A,Diretriz!B:B)),"") -> Fortalecimento da Assistência Especializada em Saúde, de Média e Alta Complexidade, de forma ascendente e regionalizada, contemplando as demandas específicas das regiões de saúde, aperfeiçoando o sistema de regulação, garantindo a oferta de serviços de saúde. | C186: 2.1 | D186: =IFERROR((_xlfn.XLOOKUP(C186,Objetivo!C:C,Objetivo!D:D)), "") -> Garantir a integralidade da assistência dos serviços de média e alta complexidade aos usuários do SUS, por meio do fortalecimento das redes de atenção à saúde. | E186: 2.1.5 | F186: =IFERROR(_xlfn.XLOOKUP(E186,#REF!,#REF!), "") | G186: 2.1.5.1 | H186: Acompanhar a validação dos protocolos clínicos e de acesso e diretrizes terapêuticas para consultas e exames especializados. | I186: Protocolos Validados | J186: Unidade | K186: 6
A187: 2 | B187: =IFERROR((_xlfn.XLOOKUP(A187,Diretriz!A:A,Diretriz!B:B)),"") -> Fortalecimento da Assistência Especializada em Saúde, de Média e Alta Complexidade, de forma ascendente e regionalizada, contemplando as demandas específicas das regiões de saúde, aperfeiçoando o sistema de regulação, garantindo a oferta de serviços de saúde. | C187: 2.1 | D187: =IFERROR((_xlfn.XLOOKUP(C187,Objetivo!C:C,Objetivo!D:D)), "") -> Garantir a integralidade da assistência dos serviços de média e alta complexidade aos usuários do SUS, por meio do fortalecimento das redes de atenção à saúde. | E187: 2.1.5 | F187: =IFERROR(_xlfn.XLOOKUP(E187,#REF!,#REF!), "") | G187: 2.1.5.2 | H187: Capacitar profissionais envolvidos no processo de regulação | I187: Capacitações Realizadas | J187: Unidade | K187: 12
... A245: 2 | B245: =IFERROR((_xlfn.XLOOKUP(A245,Diretriz!A:A,Diretriz!B:B)),"") -> Fortalecimento da Assistência Especializada em Saúde, de Média e Alta Complexidade, de forma ascendente e regionalizada, contemplando as demandas específicas das regiões de saúde, aperfeiçoando o sistema de regulação, garantindo a oferta de serviços de saúde. | C245: 2.5 | D245: =IFERROR((_xlfn.XLOOKUP(C245,Objetivo!C:C,Objetivo!D:D)), "") -> Ampliar e modernizar a infraestrutura de unidades de saúde, de acordo com perfil assistencial definido. | E245: 2.4.2 | F245: =IFERROR(_xlfn.XLOOKUP(E245,#REF!,#REF!), "") | G245: 2.4.2.1 | H245: Realizar mutirões de cirurgias oncológicas. | I245: Cirurgias realizadas | J245: Unidade | K245: 1000
E246: 2.5.1 | F246: =IFERROR(_xlfn.XLOOKUP(E246,#REF!,#REF!), "") | G246: 2.5.1.1 | H246: Ampliar e modernizar Hospital Materno Infantil de Imperatriz | I246: Obra Realizada | J246: Unidade | K246: 1
E247: 2.5.1 | G247: 2.5.1.2 | H247: Implantar Centro de Hemodiálise Colinas | I247: Obra Realizada | J247: Unidade | K247: 1
E248: 2.5.1 | G248: 2.5.1.3 | H248: Reformar UTI Genésio Rêgo | I248: Obra Realizada | J248: Unidade | K248: 1
E249: 2.5.1 | G249: 2.5.1.4 | H249: Reformar CME e Clínica Médica Aquiles Lisboa | I249: Obra Realizada | J249: Unidade | K249: 1
E250: 2.5.1 | G250: 2.5.1.5 | H250: Reformar Hospital de Referência de Doenças Tropicais- Presidente Vargas | I250: Obra Realizada | J250: Unidade | K250: 1
E251: 2.5.1 | G251: 2.5.1.6 | H251: Adequar a estrutura física do Centro de Especialidades Ninar atendendo pessoas com deficiência física, intelectual e síndromes raras | I251: Obra Realizada | J251: Unidade | K251: 1
E252: 2.5.1 | G252: 2.5.1.7 | H252: Reestruturar o espaço físico do Programa Leite Especial na Unidade de atendimento Hospital Infantil Dr. Juvêncio Matos | I252: Obra Realizada | J252: Unidade | K252: 1
E253: 2.5.1 | G253: 2.5.1.8 | H253: Implantar Centro de Hemodiálise de Viana | I253: Obra Realizada | J253: Unidade | K253: 1
E254: 2.5.1 | G254: 2.5.1.9 | H254: Implantar Centro de Hemodiálise de Lago da Pedra | I254: Obra Realizada | J254: Unidade | K254: 1
E255: 2.5.1 | G255: 2.5.1.10 | H255: Implantar Centro de Hemodiálise de Santa Luzia do Paruá | I255: Obra Realizada | J255: Unidade | K255: 1
...

Sheet (misc) bot de cod mun
K1: {=_xlfn._xlws.FILTER(C:C,C:C<>FALSE)} -> #REF!
O2: ESSA PLANILHA SERVE APENAS PARA CONSEGUIR O CÓDIGO DOS MUNICÍPIOS BENEFICIADOS. COLOCA A REGIÃO E O MUNICÍPIO BENEFICIADO EM A E B, E DAÍ AS FORMULAS VÃO ESTAR EM K.
A3: Região de Saúde | B3: O município foi beneficiado do 1º Quadrimestre? | C3: Fórmula
A4: AÇAILÂNDIA (Região XIV) | B4: Sim | C4: =IF(B4="Sim",(_xlfn.XLOOKUP('(misc) bot de cod mun'!A4,#REF!,#REF!))) -> #REF!
A5: CAXIAS (Região XXVI) | B5: Sim | C5: =IF(B5="Sim",(_xlfn.XLOOKUP('(misc) bot de cod mun'!A5,#REF!,#REF!))) -> #REF!
A6: CHAPADINHA (Região IV) | C6: =IF(B6="Sim",(_xlfn.XLOOKUP('(misc) bot de cod mun'!A6,#REF!,#REF!))) -> FALSE
A7: SÃO LUÍS (Região I) | C7: =IF(B7="Sim",(_xlfn.XLOOKUP('(misc) bot de cod mun'!A7,#REF!,#REF!))) -> FALSE
A8: CAXIAS (Região XXVI) | B8: Sim | C8: =IF(B8="Sim",(_xlfn.XLOOKUP('(misc) bot de cod mun'!A8,#REF!,#REF!))) -> #REF!
A9: BACABAL (Região XXV) | C9: =IF(B9="Sim",(_xlfn.XLOOKUP('(misc) bot de cod mun'!A9,#REF!,#REF!))) -> FALSE
A10: CODÓ (Região VI) | C10: =IF(B10="Sim",(_xlfn.XLOOKUP('(misc) bot de cod mun'!A10,#REF!,#REF!))) -> FALSE
A11: SANTA INÊS (Região XI) | C11: =IF(B11="Sim",(_xlfn.XLOOKUP('(misc) bot de cod mun'!A11,#REF!,#REF!))) -> FALSE
A12: BALSAS (Região XVII) | B12: Sim | C12: =IF(B12="Sim",(_xlfn.XLOOKUP('(misc) bot de cod mun'!A12,#REF!,#REF!))) -> #REF!
A13: ZÉ DOCA (Região XII) | C13: =IF(B13="Sim",(_xlfn.XLOOKUP('(misc) bot de cod mun'!A13,#REF!,#REF!))) -> FALSE
A14: IMPERATRIZ (Região XV) | B14: Sim | C14: =IF(B14="Sim",(_xlfn.XLOOKUP('(misc) bot de cod mun'!A14,#REF!,#REF!))) -> #REF!
A15: ITAPECURU (Região III) | C15: =IF(B15="Sim",(_xlfn.XLOOKUP('(misc) bot de cod mun'!A15,#REF!,#REF!))) -> FALSE
A16: CHAPADINHA (Região IV) | C16: =IF(B16="Sim",(_xlfn.XLOOKUP('(misc) bot de cod mun'!A16,#REF!,#REF!))) -> FALSE
A17: PINHEIRO (Região VII) | C17: =IF(B17="Sim",(_xlfn.XLOOKUP('(misc) bot de cod mun'!A17,#REF!,#REF!))) -> FALSE
A18: ZÉ DOCA (Região XII) | C18: =IF(B18="Sim",(_xlfn.XLOOKUP('(misc) bot de cod mun'!A18,#REF!,#REF!))) -> FALSE
A19: CHAPADINHA (Região IV) | C19: =IF(B19="Sim",(_xlfn.XLOOKUP('(misc) bot de cod mun'!A19,#REF!,#REF!))) -> FALSE
A20: BARRA DO CORDA (Região XXIV) | C20: =IF(B20="Sim",(_xlfn.XLOOKUP('(misc) bot de cod mun'!A20,#REF!,#REF!))) -> FALSE
A21: ITAPECURU (Região III) | C21: =IF(B21="Sim",(_xlfn.XLOOKUP('(misc) bot de cod mun'!A21,#REF!,#REF!))) -> FALSE
A22: ROSÁRIO (Região I) | C22: =IF(B22="Sim",(_xlfn.XLOOKUP('(misc) bot de cod mun'!A22,#REF!,#REF!))) -> FALSE
A23: BACABAL (Região XXV) | B23: Sim | C23: =IF(B23="Sim",(_xlfn.XLOOKUP('(misc) bot de cod mun'!A23,#REF!,#REF!))) -> #REF!
A24: ROSÁRIO (Região I) | B24: Sim | C24: =IF(B24="Sim",(_xlfn.XLOOKUP('(misc) bot de cod mun'!A24,#REF!,#REF!))) -> #REF!
A25: PINHEIRO (Região VII) | C25: =IF(B25="Sim",(_xlfn.XLOOKUP('(misc) bot de cod mun'!A25,#REF!,#REF!))) -> FALSE
A26: VIANA (Região IX) | C26: =IF(B26="Sim",(_xlfn.XLOOKUP('(misc) bot de cod mun'!A26,#REF!,#REF!))) -> FALSE
A27: BALSAS (Região XVII) | B27: Sim | C27: =IF(B27="Sim",(_xlfn.XLOOKUP('(misc) bot de cod mun'!A27,#REF!,#REF!))) -> #REF!
A28: SÃO JOÃO DOS PATOS (Região XVIII) | C28: =IF(B28="Sim",(_xlfn.XLOOKUP('(misc) bot de cod mun'!A28,#REF!,#REF!))) -> FALSE
A29: BARRA DO CORDA (Região XXIV) | B29: Sim | C29: =IF(B29="Sim",(_xlfn.XLOOKUP('(misc) bot de cod mun'!A29,#REF!,#REF!))) -> #REF!
A30: ROSÁRIO (Região I) | C30: =IF(B30="Sim",(_xlfn.XLOOKUP('(misc) bot de cod mun'!A30,#REF!,#REF!))) -> FALSE
A31: ITAPECURU (Região III) | C31: =IF(B31="Sim",(_xlfn.XLOOKUP('(misc) bot de cod mun'!A31,#REF!,#REF!))) -> FALSE
A32: SANTA INÊS (Região XI) | C32: =IF(B32="Sim",(_xlfn.XLOOKUP('(misc) bot de cod mun'!A32,#REF!,#REF!))) -> FALSE
A33: SÃO JOÃO DOS PATOS (Região XVIII) | C33: =IF(B33="Sim",(_xlfn.XLOOKUP('(misc) bot de cod mun'!A33,#REF!,#REF!))) -> FALSE
A34: PINHEIRO (Região VII) | C34: =IF(B34="Sim",(_xlfn.XLOOKUP('(misc) bot de cod mun'!A34,#REF!,#REF!))) -> FALSE
A35: PEDREIRAS (Região XXIII) | C35: =IF(B35="Sim",(_xlfn.XLOOKUP('(misc) bot de cod mun'!A35,#REF!,#REF!))) -> FALSE
A36: ZÉ DOCA (Região XII) | C36: =IF(B36="Sim",(_xlfn.XLOOKUP('(misc) bot de cod mun'!A36,#REF!,#REF!))) -> FALSE
A37: SANTA INÊS (Região XI) | C37: =IF(B37="Sim",(_xlfn.XLOOKUP('(misc) bot de cod mun'!A37,#REF!,#REF!))) -> FALSE
A38: AÇAILÂNDIA (Região XIV) | C38: =IF(B38="Sim",(_xlfn.XLOOKUP('(misc) bot de cod mun'!A38,#REF!,#REF!))) -> FALSE
A39: BACABAL (Região XXV) | C39: =IF(B39="Sim",(_xlfn.XLOOKUP('(misc) bot de cod mun'!A39,#REF!,#REF!))) -> FALSE
A40: CHAPADINHA (Região IV) | C40: =IF(B40="Sim",(_xlfn.XLOOKUP('(misc) bot de cod mun'!A40,#REF!,#REF!))) -> FALSE
...
